2022-03-08 16:22:31,221 (9562/MainThread) pgcli.main INFO - Default pager found in PAGER environment variable: "less"
2022-03-08 16:22:40,184 (9562/MainThread) pgcli.pgexecute ERROR - sql: 'select * from *', error: SyntaxError('syntax error at or near "*"\nLINE 1: select * from *\n                      ^\n')
2022-03-08 16:22:40,185 (9562/MainThread) pgcli.pgexecute ERROR - traceback: 'Traceback (most recent call last):\n  File "/usr/lib/python3.10/site-packages/pgcli/pgexecute.py", line 472, in run\n    yield self.execute_normal_sql(sql) + (sql, True, False)\n  File "/usr/lib/python3.10/site-packages/pgcli/pgexecute.py", line 507, in execute_normal_sql\n    cur.execute(split_sql)\n  File "/usr/lib/python3.10/site-packages/pgcli/pgexecute.py", line 168, in execute\n    psycopg2.extensions.cursor.execute(self, sql, args)\npsycopg2.errors.SyntaxError: syntax error at or near "*"\nLINE 1: select * from *\n                      ^\n\n'
2022-03-08 16:22:44,620 (9562/MainThread) pgcli.pgexecute ERROR - sql: 'select * from public', error: UndefinedTable('relation "public" does not exist\nLINE 1: select * from public\n                      ^\n')
2022-03-08 16:22:44,620 (9562/MainThread) pgcli.pgexecute ERROR - traceback: 'Traceback (most recent call last):\n  File "/usr/lib/python3.10/site-packages/pgcli/pgexecute.py", line 472, in run\n    yield self.execute_normal_sql(sql) + (sql, True, False)\n  File "/usr/lib/python3.10/site-packages/pgcli/pgexecute.py", line 507, in execute_normal_sql\n    cur.execute(split_sql)\n  File "/usr/lib/python3.10/site-packages/pgcli/pgexecute.py", line 168, in execute\n    psycopg2.extensions.cursor.execute(self, sql, args)\npsycopg2.errors.UndefinedTable: relation "public" does not exist\nLINE 1: select * from public\n                      ^\n\n'
2022-03-08 16:29:16,771 (3126/MainThread) pgcli.main INFO - Default pager found in PAGER environment variable: "less"
2022-03-08 16:29:16,791 (3126/MainThread) pgcli.main ERROR - traceback: 'Traceback (most recent call last):\n  File "/usr/lib/python3.10/site-packages/pgcli/main.py", line 672, in connect\n    raise e\n  File "/usr/lib/python3.10/site-packages/pgcli/main.py", line 659, in connect\n    pgexecute = PGExecute(database, user, passwd, host, port, dsn, **kwargs)\n  File "/usr/lib/python3.10/site-packages/pgcli/pgexecute.py", line 260, in __init__\n    self.connect(database, user, password, host, port, dsn, **kwargs)\n  File "/usr/lib/python3.10/site-packages/pgcli/pgexecute.py", line 306, in connect\n    conn = psycopg2.connect(**conn_params)\n  File "/usr/lib/python3.10/site-packages/psycopg2/__init__.py", line 122, in connect\n    conn = _connect(dsn, connection_factory=connection_factory, **kwasync)\npsycopg2.OperationalError: could not connect to server: Connection refused\n\tIs the server running on host "localhost" (::1) and accepting\n\tTCP/IP connections on port 5432?\ncould not connect to server: Connection refused\n\tIs the server running on host "localhost" (127.0.0.1) and accepting\n\tTCP/IP connections on port 5432?\n\n'
2022-03-08 16:31:07,436 (4623/MainThread) pgcli.main INFO - Default pager found in PAGER environment variable: "less"
2022-03-08 16:41:08,085 (11721/MainThread) pgcli.main INFO - Default pager found in PAGER environment variable: "less"
2022-03-08 16:43:50,199 (13363/MainThread) pgcli.main INFO - Default pager found in PAGER environment variable: "less"
2022-03-08 16:44:16,209 (13798/MainThread) pgcli.main INFO - Default pager found in PAGER environment variable: "less"
2022-03-08 16:45:57,713 (15081/MainThread) pgcli.main INFO - Default pager found in PAGER environment variable: "less"
2022-03-08 16:48:49,173 (17485/MainThread) pgcli.main INFO - Default pager found in PAGER environment variable: "less"
2022-03-08 16:49:30,185 (18048/MainThread) pgcli.main INFO - Default pager found in PAGER environment variable: "less"
2022-03-08 16:50:12,364 (18672/MainThread) pgcli.main INFO - Default pager found in PAGER environment variable: "less"
2022-03-08 16:51:32,791 (19582/MainThread) pgcli.main INFO - Default pager found in PAGER environment variable: "less"
2022-03-08 16:53:06,843 (22158/MainThread) pgcli.main INFO - Default pager found in PAGER environment variable: "less"
2022-03-08 16:54:04,808 (22779/MainThread) pgcli.main INFO - Default pager found in PAGER environment variable: "less"
2022-03-08 16:54:26,830 (22779/MainThread) pgcli.pgexecute ERROR - sql: 'woof', error: SyntaxError('syntax error at or near "woof"\nLINE 1: woof\n        ^\n')
2022-03-08 16:54:26,831 (22779/MainThread) pgcli.pgexecute ERROR - traceback: 'Traceback (most recent call last):\n  File "/usr/lib/python3.10/site-packages/pgcli/pgexecute.py", line 472, in run\n    yield self.execute_normal_sql(sql) + (sql, True, False)\n  File "/usr/lib/python3.10/site-packages/pgcli/pgexecute.py", line 507, in execute_normal_sql\n    cur.execute(split_sql)\n  File "/usr/lib/python3.10/site-packages/pgcli/pgexecute.py", line 168, in execute\n    psycopg2.extensions.cursor.execute(self, sql, args)\npsycopg2.errors.SyntaxError: syntax error at or near "woof"\nLINE 1: woof\n        ^\n\n'
2022-03-08 17:18:32,648 (31442/MainThread) pgcli.main INFO - Default pager found in PAGER environment variable: "less"
2022-03-08 17:19:36,137 (31442/MainThread) pgcli.pgexecute ERROR - sql: 'ls', error: SyntaxError('syntax error at or near "ls"\nLINE 1: ls\n        ^\n')
2022-03-08 17:19:36,138 (31442/MainThread) pgcli.pgexecute ERROR - traceback: 'Traceback (most recent call last):\n  File "/usr/lib/python3.10/site-packages/pgcli/pgexecute.py", line 472, in run\n    yield self.execute_normal_sql(sql) + (sql, True, False)\n  File "/usr/lib/python3.10/site-packages/pgcli/pgexecute.py", line 507, in execute_normal_sql\n    cur.execute(split_sql)\n  File "/usr/lib/python3.10/site-packages/pgcli/pgexecute.py", line 168, in execute\n    psycopg2.extensions.cursor.execute(self, sql, args)\npsycopg2.errors.SyntaxError: syntax error at or near "ls"\nLINE 1: ls\n        ^\n\n'
2022-03-08 17:22:06,559 (36735/MainThread) pgcli.main INFO - Default pager found in PAGER environment variable: "less"
2022-03-08 17:22:28,875 (37202/MainThread) pgcli.main INFO - Default pager found in PAGER environment variable: "less"
2022-03-08 17:23:54,839 (38028/MainThread) pgcli.main INFO - Default pager found in PAGER environment variable: "less"
2022-03-08 17:24:17,356 (38284/MainThread) pgcli.main INFO - Default pager found in PAGER environment variable: "less"
2022-03-08 17:29:26,241 (42129/MainThread) pgcli.main INFO - Default pager found in PAGER environment variable: "less"
2022-03-08 17:32:18,171 (44359/MainThread) pgcli.main INFO - Default pager found in PAGER environment variable: "less"
2022-03-08 17:35:24,962 (42129/MainThread) pgcli.pgexecute ERROR - sql: 'select * from cross join subregiao where cidade.codigo_subregiao = subregiao.codigo_subregiao', error: SyntaxError('syntax error at or near "join"\nLINE 1: select * from cross join subregiao where cidade.codigo_subre...\n                            ^\n')
2022-03-08 17:35:24,965 (42129/MainThread) pgcli.pgexecute ERROR - traceback: 'Traceback (most recent call last):\n  File "/usr/lib/python3.10/site-packages/pgcli/pgexecute.py", line 472, in run\n    yield self.execute_normal_sql(sql) + (sql, True, False)\n  File "/usr/lib/python3.10/site-packages/pgcli/pgexecute.py", line 507, in execute_normal_sql\n    cur.execute(split_sql)\n  File "/usr/lib/python3.10/site-packages/pgcli/pgexecute.py", line 168, in execute\n    psycopg2.extensions.cursor.execute(self, sql, args)\npsycopg2.errors.SyntaxError: syntax error at or near "join"\nLINE 1: select * from cross join subregiao where cidade.codigo_subre...\n                            ^\n\n'
2022-03-08 17:46:56,342 (42129/MainThread) pgcli.pgexecute ERROR - sql: 'select * from subregiao,pais where', error: SyntaxError('syntax error at end of input\nLINE 1: select * from subregiao,pais where\n                                          ^\n')
2022-03-08 17:46:56,342 (42129/MainThread) pgcli.pgexecute ERROR - traceback: 'Traceback (most recent call last):\n  File "/usr/lib/python3.10/site-packages/pgcli/pgexecute.py", line 472, in run\n    yield self.execute_normal_sql(sql) + (sql, True, False)\n  File "/usr/lib/python3.10/site-packages/pgcli/pgexecute.py", line 507, in execute_normal_sql\n    cur.execute(split_sql)\n  File "/usr/lib/python3.10/site-packages/pgcli/pgexecute.py", line 168, in execute\n    psycopg2.extensions.cursor.execute(self, sql, args)\npsycopg2.errors.SyntaxError: syntax error at end of input\nLINE 1: select * from subregiao,pais where\n                                          ^\n\n'
2022-03-08 17:48:26,194 (42129/MainThread) pgcli.pgexecute ERROR - sql: 'select * from cidade inner join subregiao', error: SyntaxError('syntax error at end of input\nLINE 1: select * from cidade inner join subregiao\n                                                 ^\n')
2022-03-08 17:48:26,194 (42129/MainThread) pgcli.pgexecute ERROR - traceback: 'Traceback (most recent call last):\n  File "/usr/lib/python3.10/site-packages/pgcli/pgexecute.py", line 472, in run\n    yield self.execute_normal_sql(sql) + (sql, True, False)\n  File "/usr/lib/python3.10/site-packages/pgcli/pgexecute.py", line 507, in execute_normal_sql\n    cur.execute(split_sql)\n  File "/usr/lib/python3.10/site-packages/pgcli/pgexecute.py", line 168, in execute\n    psycopg2.extensions.cursor.execute(self, sql, args)\npsycopg2.errors.SyntaxError: syntax error at end of input\nLINE 1: select * from cidade inner join subregiao\n                                                 ^\n\n'
2022-03-08 17:54:12,176 (42129/MainThread) pgcli.pgexecute ERROR - sql: 'CREATE TABLE cidade (\ncodigo_cidade SERIAL,\nnome_cidade VARCHAR(50),\ncodigo_subregiao INTEGER,\nCONSTRAINT cidade_pk PRIMARY KEY (codigo_cidade)\n)', error: DuplicateTable('relation "cidade" already exists\n')
2022-03-08 17:54:12,177 (42129/MainThread) pgcli.pgexecute ERROR - traceback: 'Traceback (most recent call last):\n  File "/usr/lib/python3.10/site-packages/pgcli/pgexecute.py", line 472, in run\n    yield self.execute_normal_sql(sql) + (sql, True, False)\n  File "/usr/lib/python3.10/site-packages/pgcli/pgexecute.py", line 507, in execute_normal_sql\n    cur.execute(split_sql)\n  File "/usr/lib/python3.10/site-packages/pgcli/pgexecute.py", line 168, in execute\n    psycopg2.extensions.cursor.execute(self, sql, args)\npsycopg2.errors.DuplicateTable: relation "cidade" already exists\n\n'
2022-03-08 17:54:12,177 (42129/MainThread) pgcli.pgexecute ERROR - sql: '\\i atv.sql', error: DuplicateTable('relation "cidade" already exists\n')
2022-03-08 17:54:12,177 (42129/MainThread) pgcli.pgexecute ERROR - traceback: 'Traceback (most recent call last):\n  File "/usr/lib/python3.10/site-packages/pgcli/pgexecute.py", line 461, in run\n    for result in response:\n  File "/usr/lib/python3.10/site-packages/pgcli/pgexecute.py", line 472, in run\n    yield self.execute_normal_sql(sql) + (sql, True, False)\n  File "/usr/lib/python3.10/site-packages/pgcli/pgexecute.py", line 507, in execute_normal_sql\n    cur.execute(split_sql)\n  File "/usr/lib/python3.10/site-packages/pgcli/pgexecute.py", line 168, in execute\n    psycopg2.extensions.cursor.execute(self, sql, args)\npsycopg2.errors.DuplicateTable: relation "cidade" already exists\n\n'
2022-03-08 18:05:48,212 (42129/MainThread) pgcli.main ERROR - sql: '\\c ex_bd', error: InterfaceError('only protocol 3 supported')
2022-03-08 18:05:48,213 (42129/MainThread) pgcli.main ERROR - traceback: 'Traceback (most recent call last):\n  File "/usr/lib/python3.10/site-packages/pgcli/main.py", line 746, in execute_command\n    output, query = self._evaluate_command(text)\n  File "/usr/lib/python3.10/site-packages/pgcli/main.py", line 1005, in _evaluate_command\n    for title, cur, headers, status, sql, success, is_special in res:\n  File "/usr/lib/python3.10/site-packages/pgcli/pgexecute.py", line 461, in run\n    for result in response:\n  File "/usr/lib/python3.10/site-packages/pgcli/main.py", line 397, in change_db\n    self.pgexecute.connect(\n  File "/usr/lib/python3.10/site-packages/pgcli/pgexecute.py", line 306, in connect\n    conn = psycopg2.connect(**conn_params)\n  File "/usr/lib/python3.10/site-packages/psycopg2/__init__.py", line 122, in connect\n    conn = _connect(dsn, connection_factory=connection_factory, **kwasync)\npsycopg2.InterfaceError: only protocol 3 supported\n'
2022-03-08 18:08:32,885 (42129/MainThread) pgcli.pgexecute ERROR - sql: 'create table empregado(\n    nome_empregado', error: SyntaxError('syntax error at end of input\nLINE 2:     nome_empregado\n                          ^\n')
2022-03-08 18:08:32,885 (42129/MainThread) pgcli.pgexecute ERROR - traceback: 'Traceback (most recent call last):\n  File "/usr/lib/python3.10/site-packages/pgcli/pgexecute.py", line 472, in run\n    yield self.execute_normal_sql(sql) + (sql, True, False)\n  File "/usr/lib/python3.10/site-packages/pgcli/pgexecute.py", line 507, in execute_normal_sql\n    cur.execute(split_sql)\n  File "/usr/lib/python3.10/site-packages/pgcli/pgexecute.py", line 168, in execute\n    psycopg2.extensions.cursor.execute(self, sql, args)\npsycopg2.errors.SyntaxError: syntax error at end of input\nLINE 2:     nome_empregado\n                          ^\n\n'
2022-03-08 18:10:50,722 (3002/MainThread) pgcli.main INFO - Default pager found in PAGER environment variable: "less"
2022-03-08 18:10:50,748 (3002/MainThread) pgcli.main ERROR - traceback: 'Traceback (most recent call last):\n  File "/usr/lib/python3.10/site-packages/pgcli/main.py", line 672, in connect\n    raise e\n  File "/usr/lib/python3.10/site-packages/pgcli/main.py", line 659, in connect\n    pgexecute = PGExecute(database, user, passwd, host, port, dsn, **kwargs)\n  File "/usr/lib/python3.10/site-packages/pgcli/pgexecute.py", line 260, in __init__\n    self.connect(database, user, password, host, port, dsn, **kwargs)\n  File "/usr/lib/python3.10/site-packages/pgcli/pgexecute.py", line 306, in connect\n    conn = psycopg2.connect(**conn_params)\n  File "/usr/lib/python3.10/site-packages/psycopg2/__init__.py", line 122, in connect\n    conn = _connect(dsn, connection_factory=connection_factory, **kwasync)\npsycopg2.OperationalError: could not connect to server: Connection refused\n\tIs the server running on host "localhost" (::1) and accepting\n\tTCP/IP connections on port 5432?\ncould not connect to server: Connection refused\n\tIs the server running on host "localhost" (127.0.0.1) and accepting\n\tTCP/IP connections on port 5432?\n\n'
2022-03-08 18:11:45,923 (3758/MainThread) pgcli.main INFO - Default pager found in PAGER environment variable: "less"
2022-03-08 18:11:45,937 (3758/MainThread) pgcli.main ERROR - traceback: 'Traceback (most recent call last):\n  File "/usr/lib/python3.10/site-packages/pgcli/main.py", line 672, in connect\n    raise e\n  File "/usr/lib/python3.10/site-packages/pgcli/main.py", line 659, in connect\n    pgexecute = PGExecute(database, user, passwd, host, port, dsn, **kwargs)\n  File "/usr/lib/python3.10/site-packages/pgcli/pgexecute.py", line 260, in __init__\n    self.connect(database, user, password, host, port, dsn, **kwargs)\n  File "/usr/lib/python3.10/site-packages/pgcli/pgexecute.py", line 306, in connect\n    conn = psycopg2.connect(**conn_params)\n  File "/usr/lib/python3.10/site-packages/psycopg2/__init__.py", line 122, in connect\n    conn = _connect(dsn, connection_factory=connection_factory, **kwasync)\npsycopg2.OperationalError: could not connect to server: Connection refused\n\tIs the server running on host "localhost" (::1) and accepting\n\tTCP/IP connections on port 5432?\ncould not connect to server: Connection refused\n\tIs the server running on host "localhost" (127.0.0.1) and accepting\n\tTCP/IP connections on port 5432?\n\n'
2022-03-08 18:12:23,485 (4733/MainThread) pgcli.main INFO - Default pager found in PAGER environment variable: "less"
2022-03-08 18:12:43,444 (5563/MainThread) pgcli.main INFO - Default pager found in PAGER environment variable: "less"
2022-03-08 18:27:06,314 (5563/MainThread) pgcli.pgexecute ERROR - sql: 'CONNECT exercicios_slides', error: SyntaxError('syntax error at or near "CONNECT"\nLINE 1: CONNECT exercicios_slides\n        ^\n')
2022-03-08 18:27:06,315 (5563/MainThread) pgcli.pgexecute ERROR - traceback: 'Traceback (most recent call last):\n  File "/usr/lib/python3.10/site-packages/pgcli/pgexecute.py", line 472, in run\n    yield self.execute_normal_sql(sql) + (sql, True, False)\n  File "/usr/lib/python3.10/site-packages/pgcli/pgexecute.py", line 507, in execute_normal_sql\n    cur.execute(split_sql)\n  File "/usr/lib/python3.10/site-packages/pgcli/pgexecute.py", line 168, in execute\n    psycopg2.extensions.cursor.execute(self, sql, args)\npsycopg2.errors.SyntaxError: syntax error at or near "CONNECT"\nLINE 1: CONNECT exercicios_slides\n        ^\n\n'
2022-03-08 18:27:06,315 (5563/MainThread) pgcli.pgexecute ERROR - sql: '\\i create_db.sql', error: SyntaxError('syntax error at or near "CONNECT"\nLINE 1: CONNECT exercicios_slides\n        ^\n')
2022-03-08 18:27:06,315 (5563/MainThread) pgcli.pgexecute ERROR - traceback: 'Traceback (most recent call last):\n  File "/usr/lib/python3.10/site-packages/pgcli/pgexecute.py", line 461, in run\n    for result in response:\n  File "/usr/lib/python3.10/site-packages/pgcli/pgexecute.py", line 472, in run\n    yield self.execute_normal_sql(sql) + (sql, True, False)\n  File "/usr/lib/python3.10/site-packages/pgcli/pgexecute.py", line 507, in execute_normal_sql\n    cur.execute(split_sql)\n  File "/usr/lib/python3.10/site-packages/pgcli/pgexecute.py", line 168, in execute\n    psycopg2.extensions.cursor.execute(self, sql, args)\npsycopg2.errors.SyntaxError: syntax error at or near "CONNECT"\nLINE 1: CONNECT exercicios_slides\n        ^\n\n'
2022-03-08 18:27:32,972 (5563/MainThread) pgcli.pgexecute ERROR - sql: 'create database exercicios_slides', error: DuplicateDatabase('database "exercicios_slides" already exists\n')
2022-03-08 18:27:32,972 (5563/MainThread) pgcli.pgexecute ERROR - traceback: 'Traceback (most recent call last):\n  File "/usr/lib/python3.10/site-packages/pgcli/pgexecute.py", line 472, in run\n    yield self.execute_normal_sql(sql) + (sql, True, False)\n  File "/usr/lib/python3.10/site-packages/pgcli/pgexecute.py", line 507, in execute_normal_sql\n    cur.execute(split_sql)\n  File "/usr/lib/python3.10/site-packages/pgcli/pgexecute.py", line 168, in execute\n    psycopg2.extensions.cursor.execute(self, sql, args)\npsycopg2.errors.DuplicateDatabase: database "exercicios_slides" already exists\n\n'
2022-03-08 18:27:43,834 (5563/MainThread) pgcli.pgexecute ERROR - sql: '-- CREATE DATABASE exercicios_slides;\n\nCREATE TABLE empregado (\n    id INTEGER PRIMARY KEY AUTOINCREMENT,\n    nome_empregado TEXT NOT NULL,\n    rua TEXT NOT NULL,\n    cidade TEXT NOT NULL,\n)', error: SyntaxError('syntax error at or near "AUTOINCREMENT"\nLINE 4:     id INTEGER PRIMARY KEY AUTOINCREMENT,\n                                   ^\n')
2022-03-08 18:27:43,834 (5563/MainThread) pgcli.pgexecute ERROR - traceback: 'Traceback (most recent call last):\n  File "/usr/lib/python3.10/site-packages/pgcli/pgexecute.py", line 472, in run\n    yield self.execute_normal_sql(sql) + (sql, True, False)\n  File "/usr/lib/python3.10/site-packages/pgcli/pgexecute.py", line 507, in execute_normal_sql\n    cur.execute(split_sql)\n  File "/usr/lib/python3.10/site-packages/pgcli/pgexecute.py", line 168, in execute\n    psycopg2.extensions.cursor.execute(self, sql, args)\npsycopg2.errors.SyntaxError: syntax error at or near "AUTOINCREMENT"\nLINE 4:     id INTEGER PRIMARY KEY AUTOINCREMENT,\n                                   ^\n\n'
2022-03-08 18:27:43,834 (5563/MainThread) pgcli.pgexecute ERROR - sql: '\\i create_db.sql', error: SyntaxError('syntax error at or near "AUTOINCREMENT"\nLINE 4:     id INTEGER PRIMARY KEY AUTOINCREMENT,\n                                   ^\n')
2022-03-08 18:27:43,835 (5563/MainThread) pgcli.pgexecute ERROR - traceback: 'Traceback (most recent call last):\n  File "/usr/lib/python3.10/site-packages/pgcli/pgexecute.py", line 461, in run\n    for result in response:\n  File "/usr/lib/python3.10/site-packages/pgcli/pgexecute.py", line 472, in run\n    yield self.execute_normal_sql(sql) + (sql, True, False)\n  File "/usr/lib/python3.10/site-packages/pgcli/pgexecute.py", line 507, in execute_normal_sql\n    cur.execute(split_sql)\n  File "/usr/lib/python3.10/site-packages/pgcli/pgexecute.py", line 168, in execute\n    psycopg2.extensions.cursor.execute(self, sql, args)\npsycopg2.errors.SyntaxError: syntax error at or near "AUTOINCREMENT"\nLINE 4:     id INTEGER PRIMARY KEY AUTOINCREMENT,\n                                   ^\n\n'
2022-03-08 18:31:33,365 (5563/MainThread) pgcli.pgexecute ERROR - sql: '-- CREATE DATABASE exercicios_slides;\n\nCREATE TABLE empregado (\n    id SERIAL PRIMARY KEY,\n    nome_empregado TEXT NOT NULL,\n    rua TEXT NOT NULL,\n    cidade TEXT NOT NULL,\n)', error: SyntaxError('syntax error at or near ")"\nLINE 8: )\n        ^\n')
2022-03-08 18:31:33,365 (5563/MainThread) pgcli.pgexecute ERROR - traceback: 'Traceback (most recent call last):\n  File "/usr/lib/python3.10/site-packages/pgcli/pgexecute.py", line 472, in run\n    yield self.execute_normal_sql(sql) + (sql, True, False)\n  File "/usr/lib/python3.10/site-packages/pgcli/pgexecute.py", line 507, in execute_normal_sql\n    cur.execute(split_sql)\n  File "/usr/lib/python3.10/site-packages/pgcli/pgexecute.py", line 168, in execute\n    psycopg2.extensions.cursor.execute(self, sql, args)\npsycopg2.errors.SyntaxError: syntax error at or near ")"\nLINE 8: )\n        ^\n\n'
2022-03-08 18:31:33,365 (5563/MainThread) pgcli.pgexecute ERROR - sql: '\\i create_db.sql', error: SyntaxError('syntax error at or near ")"\nLINE 8: )\n        ^\n')
2022-03-08 18:31:33,365 (5563/MainThread) pgcli.pgexecute ERROR - traceback: 'Traceback (most recent call last):\n  File "/usr/lib/python3.10/site-packages/pgcli/pgexecute.py", line 461, in run\n    for result in response:\n  File "/usr/lib/python3.10/site-packages/pgcli/pgexecute.py", line 472, in run\n    yield self.execute_normal_sql(sql) + (sql, True, False)\n  File "/usr/lib/python3.10/site-packages/pgcli/pgexecute.py", line 507, in execute_normal_sql\n    cur.execute(split_sql)\n  File "/usr/lib/python3.10/site-packages/pgcli/pgexecute.py", line 168, in execute\n    psycopg2.extensions.cursor.execute(self, sql, args)\npsycopg2.errors.SyntaxError: syntax error at or near ")"\nLINE 8: )\n        ^\n\n'
2022-03-08 18:32:11,341 (5563/MainThread) pgcli.pgexecute ERROR - sql: '-- CREATE DATABASE exercicios_slides;\n\nCREATE TABLE empregado (\n    id SERIAL PRIMARY KEY,\n    nome_empregado VARCHAR NOT NULL,\n    rua VARCHAR NOT NULL,\n    cidade VARCHAR NOT NULL,\n)', error: SyntaxError('syntax error at or near ")"\nLINE 8: )\n        ^\n')
2022-03-08 18:32:11,342 (5563/MainThread) pgcli.pgexecute ERROR - traceback: 'Traceback (most recent call last):\n  File "/usr/lib/python3.10/site-packages/pgcli/pgexecute.py", line 472, in run\n    yield self.execute_normal_sql(sql) + (sql, True, False)\n  File "/usr/lib/python3.10/site-packages/pgcli/pgexecute.py", line 507, in execute_normal_sql\n    cur.execute(split_sql)\n  File "/usr/lib/python3.10/site-packages/pgcli/pgexecute.py", line 168, in execute\n    psycopg2.extensions.cursor.execute(self, sql, args)\npsycopg2.errors.SyntaxError: syntax error at or near ")"\nLINE 8: )\n        ^\n\n'
2022-03-08 18:32:11,342 (5563/MainThread) pgcli.pgexecute ERROR - sql: '\\i create_db.sql', error: SyntaxError('syntax error at or near ")"\nLINE 8: )\n        ^\n')
2022-03-08 18:32:11,342 (5563/MainThread) pgcli.pgexecute ERROR - traceback: 'Traceback (most recent call last):\n  File "/usr/lib/python3.10/site-packages/pgcli/pgexecute.py", line 461, in run\n    for result in response:\n  File "/usr/lib/python3.10/site-packages/pgcli/pgexecute.py", line 472, in run\n    yield self.execute_normal_sql(sql) + (sql, True, False)\n  File "/usr/lib/python3.10/site-packages/pgcli/pgexecute.py", line 507, in execute_normal_sql\n    cur.execute(split_sql)\n  File "/usr/lib/python3.10/site-packages/pgcli/pgexecute.py", line 168, in execute\n    psycopg2.extensions.cursor.execute(self, sql, args)\npsycopg2.errors.SyntaxError: syntax error at or near ")"\nLINE 8: )\n        ^\n\n'
2022-03-08 18:33:22,148 (5563/MainThread) pgcli.pgexecute ERROR - sql: 'CREATE TABLE gerente (\n  id_empregado INTEGER NOT NULL,\n  id_gerente INTEGER NOT NULL,\n\n  FOREIGN KEY(id_empregado) REFERENCES empregado(id),\n  FOREIGN KEY(id_gerente) REFERENCES empregado(id,\n\n  PRIMARY KEY(id_gerente, id_empregado)\n)', error: SyntaxError('syntax error at or near "PRIMARY"\nLINE 8:   PRIMARY KEY(id_gerente, id_empregado)\n          ^\n')
2022-03-08 18:33:22,148 (5563/MainThread) pgcli.pgexecute ERROR - traceback: 'Traceback (most recent call last):\n  File "/usr/lib/python3.10/site-packages/pgcli/pgexecute.py", line 472, in run\n    yield self.execute_normal_sql(sql) + (sql, True, False)\n  File "/usr/lib/python3.10/site-packages/pgcli/pgexecute.py", line 507, in execute_normal_sql\n    cur.execute(split_sql)\n  File "/usr/lib/python3.10/site-packages/pgcli/pgexecute.py", line 168, in execute\n    psycopg2.extensions.cursor.execute(self, sql, args)\npsycopg2.errors.SyntaxError: syntax error at or near "PRIMARY"\nLINE 8:   PRIMARY KEY(id_gerente, id_empregado)\n          ^\n\n'
2022-03-08 18:33:22,148 (5563/MainThread) pgcli.pgexecute ERROR - sql: '\\i create_db.sql', error: SyntaxError('syntax error at or near "PRIMARY"\nLINE 8:   PRIMARY KEY(id_gerente, id_empregado)\n          ^\n')
2022-03-08 18:33:22,149 (5563/MainThread) pgcli.pgexecute ERROR - traceback: 'Traceback (most recent call last):\n  File "/usr/lib/python3.10/site-packages/pgcli/pgexecute.py", line 461, in run\n    for result in response:\n  File "/usr/lib/python3.10/site-packages/pgcli/pgexecute.py", line 472, in run\n    yield self.execute_normal_sql(sql) + (sql, True, False)\n  File "/usr/lib/python3.10/site-packages/pgcli/pgexecute.py", line 507, in execute_normal_sql\n    cur.execute(split_sql)\n  File "/usr/lib/python3.10/site-packages/pgcli/pgexecute.py", line 168, in execute\n    psycopg2.extensions.cursor.execute(self, sql, args)\npsycopg2.errors.SyntaxError: syntax error at or near "PRIMARY"\nLINE 8:   PRIMARY KEY(id_gerente, id_empregado)\n          ^\n\n'
2022-03-08 18:33:40,633 (5563/MainThread) pgcli.pgexecute ERROR - sql: '-- CREATE DATABASE exercicios_slides;\n\nCREATE TABLE empregado (\n    id SERIAL PRIMARY KEY,\n    nome_empregado TEXT NOT NULL,\n    rua TEXT NOT NULL,\n    cidade TEXT NOT NULL\n)', error: DuplicateTable('relation "empregado" already exists\n')
2022-03-08 18:33:40,634 (5563/MainThread) pgcli.pgexecute ERROR - traceback: 'Traceback (most recent call last):\n  File "/usr/lib/python3.10/site-packages/pgcli/pgexecute.py", line 472, in run\n    yield self.execute_normal_sql(sql) + (sql, True, False)\n  File "/usr/lib/python3.10/site-packages/pgcli/pgexecute.py", line 507, in execute_normal_sql\n    cur.execute(split_sql)\n  File "/usr/lib/python3.10/site-packages/pgcli/pgexecute.py", line 168, in execute\n    psycopg2.extensions.cursor.execute(self, sql, args)\npsycopg2.errors.DuplicateTable: relation "empregado" already exists\n\n'
2022-03-08 18:33:40,634 (5563/MainThread) pgcli.pgexecute ERROR - sql: '\\i create_db.sql', error: DuplicateTable('relation "empregado" already exists\n')
2022-03-08 18:33:40,634 (5563/MainThread) pgcli.pgexecute ERROR - traceback: 'Traceback (most recent call last):\n  File "/usr/lib/python3.10/site-packages/pgcli/pgexecute.py", line 461, in run\n    for result in response:\n  File "/usr/lib/python3.10/site-packages/pgcli/pgexecute.py", line 472, in run\n    yield self.execute_normal_sql(sql) + (sql, True, False)\n  File "/usr/lib/python3.10/site-packages/pgcli/pgexecute.py", line 507, in execute_normal_sql\n    cur.execute(split_sql)\n  File "/usr/lib/python3.10/site-packages/pgcli/pgexecute.py", line 168, in execute\n    psycopg2.extensions.cursor.execute(self, sql, args)\npsycopg2.errors.DuplicateTable: relation "empregado" already exists\n\n'
2022-03-08 18:43:09,507 (5563/MainThread) pgcli.pgexecute ERROR - sql: 'INSERT INTO empregado (nome_empregado,rua,cidade) VALUES ( "João", "Rua da Paz", "São Paulo")', error: UndefinedColumn('column "João" does not exist\nLINE 1: ...TO empregado (nome_empregado,rua,cidade) VALUES ( "João", "R...\n                                                             ^\n')
2022-03-08 18:43:09,507 (5563/MainThread) pgcli.pgexecute ERROR - traceback: 'Traceback (most recent call last):\n  File "/usr/lib/python3.10/site-packages/pgcli/pgexecute.py", line 472, in run\n    yield self.execute_normal_sql(sql) + (sql, True, False)\n  File "/usr/lib/python3.10/site-packages/pgcli/pgexecute.py", line 507, in execute_normal_sql\n    cur.execute(split_sql)\n  File "/usr/lib/python3.10/site-packages/pgcli/pgexecute.py", line 168, in execute\n    psycopg2.extensions.cursor.execute(self, sql, args)\npsycopg2.errors.UndefinedColumn: column "João" does not exist\nLINE 1: ...TO empregado (nome_empregado,rua,cidade) VALUES ( "João", "R...\n                                                             ^\n\n'
2022-03-08 18:43:09,507 (5563/MainThread) pgcli.pgexecute ERROR - sql: '\\i populate_db.sql', error: UndefinedColumn('column "João" does not exist\nLINE 1: ...TO empregado (nome_empregado,rua,cidade) VALUES ( "João", "R...\n                                                             ^\n')
2022-03-08 18:43:09,507 (5563/MainThread) pgcli.pgexecute ERROR - traceback: 'Traceback (most recent call last):\n  File "/usr/lib/python3.10/site-packages/pgcli/pgexecute.py", line 461, in run\n    for result in response:\n  File "/usr/lib/python3.10/site-packages/pgcli/pgexecute.py", line 472, in run\n    yield self.execute_normal_sql(sql) + (sql, True, False)\n  File "/usr/lib/python3.10/site-packages/pgcli/pgexecute.py", line 507, in execute_normal_sql\n    cur.execute(split_sql)\n  File "/usr/lib/python3.10/site-packages/pgcli/pgexecute.py", line 168, in execute\n    psycopg2.extensions.cursor.execute(self, sql, args)\npsycopg2.errors.UndefinedColumn: column "João" does not exist\nLINE 1: ...TO empregado (nome_empregado,rua,cidade) VALUES ( "João", "R...\n                                                             ^\n\n'
2022-03-08 18:46:02,470 (5563/MainThread) pgcli.pgexecute ERROR - sql: '\\', error: SyntaxError('syntax error at or near "\\"\nLINE 1: \\\n        ^\n')
2022-03-08 18:46:02,470 (5563/MainThread) pgcli.pgexecute ERROR - traceback: 'Traceback (most recent call last):\n  File "/usr/lib/python3.10/site-packages/pgcli/pgexecute.py", line 472, in run\n    yield self.execute_normal_sql(sql) + (sql, True, False)\n  File "/usr/lib/python3.10/site-packages/pgcli/pgexecute.py", line 507, in execute_normal_sql\n    cur.execute(split_sql)\n  File "/usr/lib/python3.10/site-packages/pgcli/pgexecute.py", line 168, in execute\n    psycopg2.extensions.cursor.execute(self, sql, args)\npsycopg2.errors.SyntaxError: syntax error at or near "\\"\nLINE 1: \\\n        ^\n\n'
